19-02-2024 11:20:26 - [31m[1mWARNING: This is a development server. Do not use it in a production deployment. Use a production WSGI server instead.[0m
 * Running on http://127.0.0.1:5000
19-02-2024 11:20:26 - [33mPress CTRL+C to quit[0m
19-02-2024 11:20:26 -  * Restarting with stat
19-02-2024 11:20:28 -  * Debugger is active!
19-02-2024 11:20:28 -  * Debugger PIN: 897-868-015
19-02-2024 11:20:37 - 5c63W3vsmG -  route for login
19-02-2024 11:20:37 - 5c63W3vsmG - User trying to login
19-02-2024 11:20:37 - 5c63W3vsmG - User is trying to login with username admin123
19-02-2024 11:20:37 - 127.0.0.1 - - [19/Feb/2024 11:20:37] "POST /travelmanagementsystem/signin HTTP/1.1" 200 -
19-02-2024 11:22:19 -  * Detected change in 'c:\\Users\\ashukla\\OneDrive - WatchGuard Technologies Inc\\Desktop\\Minor project\\Tours and Travel\\src\\database\\context_manager.py', reloading
19-02-2024 11:22:20 -  * Restarting with stat
19-02-2024 11:22:21 -  * Debugger is active!
19-02-2024 11:22:21 -  * Debugger PIN: 897-868-015
19-02-2024 11:22:21 -  * Detected change in 'c:\\Users\\ashukla\\OneDrive - WatchGuard Technologies Inc\\Desktop\\Minor project\\Tours and Travel\\src\\database\\context_manager.py', reloading
19-02-2024 11:22:21 -  * Restarting with stat
19-02-2024 11:22:23 -  * Debugger is active!
19-02-2024 11:22:23 -  * Debugger PIN: 897-868-015
19-02-2024 11:22:27 - CHtQUqaUHX -  route for login
19-02-2024 11:22:27 - CHtQUqaUHX - User trying to login
19-02-2024 11:22:27 - CHtQUqaUHX - User is trying to login with username admin123
19-02-2024 11:22:27 - 127.0.0.1 - - [19/Feb/2024 11:22:27] "POST /travelmanagementsystem/signin HTTP/1.1" 200 -
19-02-2024 11:22:37 -  * Detected change in 'c:\\Users\\ashukla\\OneDrive - WatchGuard Technologies Inc\\Desktop\\Minor project\\Tours and Travel\\src\\database\\context_manager.py', reloading
19-02-2024 11:22:37 -  * Restarting with stat
19-02-2024 11:22:38 -  * Debugger is active!
19-02-2024 11:22:38 -  * Debugger PIN: 897-868-015
19-02-2024 11:22:46 -  * Detected change in 'c:\\Users\\ashukla\\OneDrive - WatchGuard Technologies Inc\\Desktop\\Minor project\\Tours and Travel\\src\\handlers\\auth_handler\\login_handler.py', reloading
19-02-2024 11:22:46 -  * Restarting with stat
19-02-2024 11:23:00 - [31m[1mWARNING: This is a development server. Do not use it in a production deployment. Use a production WSGI server instead.[0m
 * Running on http://127.0.0.1:5000
19-02-2024 11:23:00 - [33mPress CTRL+C to quit[0m
19-02-2024 11:23:00 -  * Restarting with stat
19-02-2024 11:23:01 -  * Debugger is active!
19-02-2024 11:23:01 -  * Debugger PIN: 897-868-015
19-02-2024 11:23:02 - 88b5oSdhja -  route for login
19-02-2024 11:23:02 - 88b5oSdhja - User trying to login
19-02-2024 11:23:02 - 88b5oSdhja - User is trying to login with username admin123
19-02-2024 11:23:02 - 127.0.0.1 - - [19/Feb/2024 11:23:02] "POST /travelmanagementsystem/signin HTTP/1.1" 200 -
19-02-2024 11:23:13 -  * Detected change in 'c:\\Users\\ashukla\\OneDrive - WatchGuard Technologies Inc\\Desktop\\Minor project\\Tours and Travel\\src\\handlers\\auth_handler\\login_handler.py', reloading
19-02-2024 11:23:13 -  * Restarting with stat
19-02-2024 11:23:14 -  * Debugger is active!
19-02-2024 11:23:14 -  * Debugger PIN: 897-868-015
19-02-2024 11:23:22 -  * Detected change in 'c:\\Users\\ashukla\\OneDrive - WatchGuard Technologies Inc\\Desktop\\Minor project\\Tours and Travel\\src\\database\\database_access.py', reloading
19-02-2024 11:23:22 -  * Restarting with stat
19-02-2024 11:23:23 -  * Debugger is active!
19-02-2024 11:23:23 -  * Debugger PIN: 897-868-015
19-02-2024 11:23:25 - CE5hJaJZtV -  route for login
19-02-2024 11:23:25 - CE5hJaJZtV - User trying to login
19-02-2024 11:23:25 - CE5hJaJZtV - User is trying to login with username admin123
19-02-2024 11:23:25 - 127.0.0.1 - - [19/Feb/2024 11:23:25] "POST /travelmanagementsystem/signin HTTP/1.1" 200 -
19-02-2024 11:24:20 -  * Detected change in 'c:\\Users\\ashukla\\OneDrive - WatchGuard Technologies Inc\\Desktop\\Minor project\\Tours and Travel\\src\\database\\database_access.py', reloading
19-02-2024 11:24:21 -  * Restarting with stat
19-02-2024 11:24:22 -  * Debugger is active!
19-02-2024 11:24:22 -  * Debugger PIN: 897-868-015
19-02-2024 11:24:23 - GLc4sFFD8u -  route for login
19-02-2024 11:24:23 - GLc4sFFD8u - User trying to login
19-02-2024 11:24:23 - GLc4sFFD8u - User is trying to login with username admin123
19-02-2024 11:24:23 - New access and refresh token issued
19-02-2024 11:24:23 - 127.0.0.1 - - [19/Feb/2024 11:24:23] "POST /travelmanagementsystem/signin HTTP/1.1" 200 -
19-02-2024 11:24:31 -  * Detected change in 'c:\\Users\\ashukla\\OneDrive - WatchGuard Technologies Inc\\Desktop\\Minor project\\Tours and Travel\\src\\database\\database_access.py', reloading
19-02-2024 11:24:31 -  * Restarting with stat
19-02-2024 11:24:32 -  * Debugger is active!
19-02-2024 11:24:32 -  * Debugger PIN: 897-868-015
19-02-2024 11:24:37 -  * Detected change in 'c:\\Users\\ashukla\\OneDrive - WatchGuard Technologies Inc\\Desktop\\Minor project\\Tours and Travel\\src\\database\\database_access.py', reloading
19-02-2024 11:24:37 -  * Restarting with stat
19-02-2024 11:24:38 -  * Debugger is active!
19-02-2024 11:24:38 -  * Debugger PIN: 897-868-015
19-02-2024 11:24:44 - 6DQCsTC5yK -  route for posting packages
19-02-2024 11:24:44 - 6DQCsTC5yK - Creating new package
19-02-2024 11:24:44 - 6DQCsTC5yK - Adding new package
19-02-2024 11:24:44 - Added new package
19-02-2024 11:24:44 - 127.0.0.1 - - [19/Feb/2024 11:24:44] "POST /travelmanagementsystem/packages HTTP/1.1" 200 -
19-02-2024 11:24:48 - E3tUBptU46 -  route for getting packages
19-02-2024 11:24:48 - E3tUBptU46 - Getting all packages
19-02-2024 11:24:48 - <function get_request_id at 0x00000296A1924040> - Fetching all packages
19-02-2024 11:24:48 - 127.0.0.1 - - [19/Feb/2024 11:24:48] "GET /travelmanagementsystem/packages HTTP/1.1" 200 -
19-02-2024 11:25:10 -  * Detected change in 'c:\\Users\\ashukla\\OneDrive - WatchGuard Technologies Inc\\Desktop\\Minor project\\Tours and Travel\\src\\database\\database_access.py', reloading
19-02-2024 11:25:10 -  * Restarting with stat
19-02-2024 11:25:11 -  * Debugger is active!
19-02-2024 11:25:11 -  * Debugger PIN: 897-868-015
19-02-2024 11:25:18 -  * Debugger is active!
19-02-2024 11:25:18 -  * Debugger PIN: 897-868-015
19-02-2024 11:25:18 - [31m[1mWARNING: This is a development server. Do not use it in a production deployment. Use a production WSGI server instead.[0m
 * Running on http://127.0.0.1:5000
19-02-2024 11:25:18 - [33mPress CTRL+C to quit[0m
19-02-2024 11:25:18 -  * Restarting with stat
19-02-2024 11:41:46 - [31m[1mWARNING: This is a development server. Do not use it in a production deployment. Use a production WSGI server instead.[0m
 * Running on http://127.0.0.1:5000
19-02-2024 11:41:46 - [33mPress CTRL+C to quit[0m
19-02-2024 11:41:46 -  * Restarting with stat
19-02-2024 11:41:47 -  * Debugger is active!
19-02-2024 11:41:47 -  * Debugger PIN: 897-868-015
19-02-2024 11:44:33 -  * Detected change in 'c:\\Users\\ashukla\\OneDrive - WatchGuard Technologies Inc\\Desktop\\Minor project\\Tours and Travel\\src\\utils\\initialize_app.py', reloading
19-02-2024 11:44:33 -  * Restarting with stat
19-02-2024 11:44:34 -  * Debugger is active!
19-02-2024 11:44:34 -  * Debugger PIN: 897-868-015
19-02-2024 11:44:52 -  * Detected change in 'c:\\Users\\ashukla\\OneDrive - WatchGuard Technologies Inc\\Desktop\\Minor project\\Tours and Travel\\src\\app.py', reloading
19-02-2024 11:44:52 -  * Restarting with stat
19-02-2024 11:45:19 - 
Traceback (most recent call last):
  File "C:\Users\ashukla\.virtualenvs\Tours_and_Travel-ejH2dMQI\Lib\site-packages\pymysql\connections.py", line 644, in connect
    sock = socket.create_connection(
           ^^^^^^^^^^^^^^^^^^^^^^^^^
  File "C:\Program Files\Python311\Lib\socket.py", line 851, in create_connection
    raise exceptions[0]
  File "C:\Program Files\Python311\Lib\socket.py", line 836, in create_connection
    sock.connect(sa)
ConnectionRefusedError: [WinError 10061] No connection could be made because the target machine actively refused it

During handling of the above exception, another exception occurred:

Traceback (most recent call last):
  File "c:\Users\ashukla\OneDrive - WatchGuard Technologies Inc\Desktop\Minor project\Tours and Travel\src\database\context_manager.py", line 28, in setup_connection
    self.connection = pymysql.connect(
                      ^^^^^^^^^^^^^^^^
  File "C:\Users\ashukla\.virtualenvs\Tours_and_Travel-ejH2dMQI\Lib\site-packages\pymysql\connections.py", line 358, in __init__
    self.connect()
  File "C:\Users\ashukla\.virtualenvs\Tours_and_Travel-ejH2dMQI\Lib\site-packages\pymysql\connections.py", line 711, in connect
    raise exc
pymysql.err.OperationalError: (2003, "Can't connect to MySQL server on '127.0.0.1' ([WinError 10061] No connection could be made because the target machine actively refused it)")

The above exception was the direct cause of the following exception:

Traceback (most recent call last):
  File "c:\Users\ashukla\OneDrive - WatchGuard Technologies Inc\Desktop\Minor project\Tours and Travel\src\utils\initialize_app.py", line 43, in create_tables
    with DatabaseConnection() as connection:
         ^^^^^^^^^^^^^^^^^^^^
  File "c:\Users\ashukla\OneDrive - WatchGuard Technologies Inc\Desktop\Minor project\Tours and Travel\src\database\context_manager.py", line 22, in __init__
    self.setup_connection()
  File "c:\Users\ashukla\OneDrive - WatchGuard Technologies Inc\Desktop\Minor project\Tours and Travel\src\database\context_manager.py", line 46, in setup_connection
    raise pymysql.Error from e
pymysql.err.Error
19-02-2024 11:46:42 - 
Traceback (most recent call last):
  File "C:\Users\ashukla\.virtualenvs\Tours_and_Travel-ejH2dMQI\Lib\site-packages\pymysql\connections.py", line 644, in connect
    sock = socket.create_connection(
           ^^^^^^^^^^^^^^^^^^^^^^^^^
  File "C:\Program Files\Python311\Lib\socket.py", line 851, in create_connection
    raise exceptions[0]
  File "C:\Program Files\Python311\Lib\socket.py", line 836, in create_connection
    sock.connect(sa)
ConnectionRefusedError: [WinError 10061] No connection could be made because the target machine actively refused it

During handling of the above exception, another exception occurred:

Traceback (most recent call last):
  File "c:\Users\ashukla\OneDrive - WatchGuard Technologies Inc\Desktop\Minor project\Tours and Travel\src\database\context_manager.py", line 28, in setup_connection
    self.connection = pymysql.connect(
                      ^^^^^^^^^^^^^^^^
  File "C:\Users\ashukla\.virtualenvs\Tours_and_Travel-ejH2dMQI\Lib\site-packages\pymysql\connections.py", line 358, in __init__
    self.connect()
  File "C:\Users\ashukla\.virtualenvs\Tours_and_Travel-ejH2dMQI\Lib\site-packages\pymysql\connections.py", line 711, in connect
    raise exc
pymysql.err.OperationalError: (2003, "Can't connect to MySQL server on '127.0.0.1' ([WinError 10061] No connection could be made because the target machine actively refused it)")

The above exception was the direct cause of the following exception:

Traceback (most recent call last):
  File "c:\Users\ashukla\OneDrive - WatchGuard Technologies Inc\Desktop\Minor project\Tours and Travel\src\utils\initialize_app.py", line 43, in create_tables
    with DatabaseConnection() as connection:
         ^^^^^^^^^^^^^^^^^^^^
  File "c:\Users\ashukla\OneDrive - WatchGuard Technologies Inc\Desktop\Minor project\Tours and Travel\src\database\context_manager.py", line 22, in __init__
    self.setup_connection()
  File "c:\Users\ashukla\OneDrive - WatchGuard Technologies Inc\Desktop\Minor project\Tours and Travel\src\database\context_manager.py", line 46, in setup_connection
    raise pymysql.Error from e
pymysql.err.Error
19-02-2024 11:47:16 - 
Traceback (most recent call last):
  File "C:\Users\ashukla\.virtualenvs\Tours_and_Travel-ejH2dMQI\Lib\site-packages\pymysql\connections.py", line 644, in connect
    sock = socket.create_connection(
           ^^^^^^^^^^^^^^^^^^^^^^^^^
  File "C:\Program Files\Python311\Lib\socket.py", line 851, in create_connection
    raise exceptions[0]
  File "C:\Program Files\Python311\Lib\socket.py", line 836, in create_connection
    sock.connect(sa)
ConnectionRefusedError: [WinError 10061] No connection could be made because the target machine actively refused it

During handling of the above exception, another exception occurred:

Traceback (most recent call last):
  File "c:\Users\ashukla\OneDrive - WatchGuard Technologies Inc\Desktop\Minor project\Tours and Travel\src\database\context_manager.py", line 28, in setup_connection
    self.connection = pymysql.connect(
                      ^^^^^^^^^^^^^^^^
  File "C:\Users\ashukla\.virtualenvs\Tours_and_Travel-ejH2dMQI\Lib\site-packages\pymysql\connections.py", line 358, in __init__
    self.connect()
  File "C:\Users\ashukla\.virtualenvs\Tours_and_Travel-ejH2dMQI\Lib\site-packages\pymysql\connections.py", line 711, in connect
    raise exc
pymysql.err.OperationalError: (2003, "Can't connect to MySQL server on '127.0.0.1' ([WinError 10061] No connection could be made because the target machine actively refused it)")

The above exception was the direct cause of the following exception:

Traceback (most recent call last):
  File "c:\Users\ashukla\OneDrive - WatchGuard Technologies Inc\Desktop\Minor project\Tours and Travel\src\utils\initialize_app.py", line 43, in create_tables
    with DatabaseConnection() as connection:
         ^^^^^^^^^^^^^^^^^^^^
  File "c:\Users\ashukla\OneDrive - WatchGuard Technologies Inc\Desktop\Minor project\Tours and Travel\src\database\context_manager.py", line 22, in __init__
    self.setup_connection()
  File "c:\Users\ashukla\OneDrive - WatchGuard Technologies Inc\Desktop\Minor project\Tours and Travel\src\database\context_manager.py", line 46, in setup_connection
    raise pymysql.Error from e
pymysql.err.Error
19-02-2024 11:47:50 - 
Traceback (most recent call last):
  File "C:\Users\ashukla\.virtualenvs\Tours_and_Travel-ejH2dMQI\Lib\site-packages\pymysql\connections.py", line 644, in connect
    sock = socket.create_connection(
           ^^^^^^^^^^^^^^^^^^^^^^^^^
  File "C:\Program Files\Python311\Lib\socket.py", line 851, in create_connection
    raise exceptions[0]
  File "C:\Program Files\Python311\Lib\socket.py", line 836, in create_connection
    sock.connect(sa)
ConnectionRefusedError: [WinError 10061] No connection could be made because the target machine actively refused it

During handling of the above exception, another exception occurred:

Traceback (most recent call last):
  File "c:\Users\ashukla\OneDrive - WatchGuard Technologies Inc\Desktop\Minor project\Tours and Travel\src\database\context_manager.py", line 28, in setup_connection
    self.connection = pymysql.connect(
                      ^^^^^^^^^^^^^^^^
  File "C:\Users\ashukla\.virtualenvs\Tours_and_Travel-ejH2dMQI\Lib\site-packages\pymysql\connections.py", line 358, in __init__
    self.connect()
  File "C:\Users\ashukla\.virtualenvs\Tours_and_Travel-ejH2dMQI\Lib\site-packages\pymysql\connections.py", line 711, in connect
    raise exc
pymysql.err.OperationalError: (2003, "Can't connect to MySQL server on '127.0.0.1' ([WinError 10061] No connection could be made because the target machine actively refused it)")

The above exception was the direct cause of the following exception:

Traceback (most recent call last):
  File "c:\Users\ashukla\OneDrive - WatchGuard Technologies Inc\Desktop\Minor project\Tours and Travel\src\utils\initialize_app.py", line 43, in create_tables
    with DatabaseConnection() as connection:
         ^^^^^^^^^^^^^^^^^^^^
  File "c:\Users\ashukla\OneDrive - WatchGuard Technologies Inc\Desktop\Minor project\Tours and Travel\src\database\context_manager.py", line 22, in __init__
    self.setup_connection()
  File "c:\Users\ashukla\OneDrive - WatchGuard Technologies Inc\Desktop\Minor project\Tours and Travel\src\database\context_manager.py", line 47, in setup_connection
    raise pymysql.Error from e
pymysql.err.Error
19-02-2024 11:49:09 - 
Traceback (most recent call last):
  File "C:\Users\ashukla\.virtualenvs\Tours_and_Travel-ejH2dMQI\Lib\site-packages\pymysql\connections.py", line 644, in connect
    sock = socket.create_connection(
           ^^^^^^^^^^^^^^^^^^^^^^^^^
  File "C:\Program Files\Python311\Lib\socket.py", line 851, in create_connection
    raise exceptions[0]
  File "C:\Program Files\Python311\Lib\socket.py", line 836, in create_connection
    sock.connect(sa)
ConnectionRefusedError: [WinError 10061] No connection could be made because the target machine actively refused it

During handling of the above exception, another exception occurred:

Traceback (most recent call last):
  File "c:\Users\ashukla\OneDrive - WatchGuard Technologies Inc\Desktop\Minor project\Tours and Travel\src\database\context_manager.py", line 28, in setup_connection
    self.connection = pymysql.connect(
                      ^^^^^^^^^^^^^^^^
  File "C:\Users\ashukla\.virtualenvs\Tours_and_Travel-ejH2dMQI\Lib\site-packages\pymysql\connections.py", line 358, in __init__
    self.connect()
  File "C:\Users\ashukla\.virtualenvs\Tours_and_Travel-ejH2dMQI\Lib\site-packages\pymysql\connections.py", line 711, in connect
    raise exc
pymysql.err.OperationalError: (2003, "Can't connect to MySQL server on '127.0.0.1' ([WinError 10061] No connection could be made because the target machine actively refused it)")

The above exception was the direct cause of the following exception:

Traceback (most recent call last):
  File "c:\Users\ashukla\OneDrive - WatchGuard Technologies Inc\Desktop\Minor project\Tours and Travel\src\utils\initialize_app.py", line 43, in create_tables
    with DatabaseConnection() as connection:
         ^^^^^^^^^^^^^^^^^^^^
  File "c:\Users\ashukla\OneDrive - WatchGuard Technologies Inc\Desktop\Minor project\Tours and Travel\src\database\context_manager.py", line 22, in __init__
    self.setup_connection()
  File "c:\Users\ashukla\OneDrive - WatchGuard Technologies Inc\Desktop\Minor project\Tours and Travel\src\database\context_manager.py", line 47, in setup_connection
    raise pymysql.Error from e
pymysql.err.Error
19-02-2024 11:53:00 - 
Traceback (most recent call last):
  File "C:\Users\ashukla\.virtualenvs\Tours_and_Travel-ejH2dMQI\Lib\site-packages\pymysql\connections.py", line 644, in connect
    sock = socket.create_connection(
           ^^^^^^^^^^^^^^^^^^^^^^^^^
  File "C:\Program Files\Python311\Lib\socket.py", line 851, in create_connection
    raise exceptions[0]
  File "C:\Program Files\Python311\Lib\socket.py", line 836, in create_connection
    sock.connect(sa)
ConnectionRefusedError: [WinError 10061] No connection could be made because the target machine actively refused it

During handling of the above exception, another exception occurred:

Traceback (most recent call last):
  File "c:\Users\ashukla\OneDrive - WatchGuard Technologies Inc\Desktop\Minor project\Tours and Travel\src\database\context_manager.py", line 28, in setup_connection
    self.connection = pymysql.connect(
                      ^^^^^^^^^^^^^^^^
  File "C:\Users\ashukla\.virtualenvs\Tours_and_Travel-ejH2dMQI\Lib\site-packages\pymysql\connections.py", line 358, in __init__
    self.connect()
  File "C:\Users\ashukla\.virtualenvs\Tours_and_Travel-ejH2dMQI\Lib\site-packages\pymysql\connections.py", line 711, in connect
    raise exc
pymysql.err.OperationalError: (2003, "Can't connect to MySQL server on '127.0.0.1' ([WinError 10061] No connection could be made because the target machine actively refused it)")

The above exception was the direct cause of the following exception:

Traceback (most recent call last):
  File "c:\Users\ashukla\OneDrive - WatchGuard Technologies Inc\Desktop\Minor project\Tours and Travel\src\utils\initialize_app.py", line 43, in create_tables
    with DatabaseConnection() as connection:
         ^^^^^^^^^^^^^^^^^^^^
  File "c:\Users\ashukla\OneDrive - WatchGuard Technologies Inc\Desktop\Minor project\Tours and Travel\src\database\context_manager.py", line 22, in __init__
    self.setup_connection()
  File "c:\Users\ashukla\OneDrive - WatchGuard Technologies Inc\Desktop\Minor project\Tours and Travel\src\database\context_manager.py", line 48, in setup_connection
    raise pymysql.Error from e
pymysql.err.Error
19-02-2024 11:53:58 - 
Traceback (most recent call last):
  File "C:\Users\ashukla\.virtualenvs\Tours_and_Travel-ejH2dMQI\Lib\site-packages\pymysql\connections.py", line 644, in connect
    sock = socket.create_connection(
           ^^^^^^^^^^^^^^^^^^^^^^^^^
  File "C:\Program Files\Python311\Lib\socket.py", line 851, in create_connection
    raise exceptions[0]
  File "C:\Program Files\Python311\Lib\socket.py", line 836, in create_connection
    sock.connect(sa)
ConnectionRefusedError: [WinError 10061] No connection could be made because the target machine actively refused it

During handling of the above exception, another exception occurred:

Traceback (most recent call last):
  File "c:\Users\ashukla\OneDrive - WatchGuard Technologies Inc\Desktop\Minor project\Tours and Travel\src\database\context_manager.py", line 28, in setup_connection
    self.connection = pymysql.connect(
                      ^^^^^^^^^^^^^^^^
  File "C:\Users\ashukla\.virtualenvs\Tours_and_Travel-ejH2dMQI\Lib\site-packages\pymysql\connections.py", line 358, in __init__
    self.connect()
  File "C:\Users\ashukla\.virtualenvs\Tours_and_Travel-ejH2dMQI\Lib\site-packages\pymysql\connections.py", line 711, in connect
    raise exc
pymysql.err.OperationalError: (2003, "Can't connect to MySQL server on '127.0.0.1' ([WinError 10061] No connection could be made because the target machine actively refused it)")

The above exception was the direct cause of the following exception:

Traceback (most recent call last):
  File "c:\Users\ashukla\OneDrive - WatchGuard Technologies Inc\Desktop\Minor project\Tours and Travel\src\utils\initialize_app.py", line 43, in create_tables
    with DatabaseConnection() as connection:
         ^^^^^^^^^^^^^^^^^^^^
  File "c:\Users\ashukla\OneDrive - WatchGuard Technologies Inc\Desktop\Minor project\Tours and Travel\src\database\context_manager.py", line 22, in __init__
    self.setup_connection()
  File "c:\Users\ashukla\OneDrive - WatchGuard Technologies Inc\Desktop\Minor project\Tours and Travel\src\database\context_manager.py", line 48, in setup_connection
    raise pymysql.Error from e
pymysql.err.Error
19-02-2024 11:54:54 - 
Traceback (most recent call last):
  File "C:\Users\ashukla\.virtualenvs\Tours_and_Travel-ejH2dMQI\Lib\site-packages\pymysql\connections.py", line 644, in connect
    sock = socket.create_connection(
           ^^^^^^^^^^^^^^^^^^^^^^^^^
  File "C:\Program Files\Python311\Lib\socket.py", line 851, in create_connection
    raise exceptions[0]
  File "C:\Program Files\Python311\Lib\socket.py", line 836, in create_connection
    sock.connect(sa)
ConnectionRefusedError: [WinError 10061] No connection could be made because the target machine actively refused it

During handling of the above exception, another exception occurred:

Traceback (most recent call last):
  File "c:\Users\ashukla\OneDrive - WatchGuard Technologies Inc\Desktop\Minor project\Tours and Travel\src\database\context_manager.py", line 28, in setup_connection
    self.connection = pymysql.connect(
                      ^^^^^^^^^^^^^^^^
  File "C:\Users\ashukla\.virtualenvs\Tours_and_Travel-ejH2dMQI\Lib\site-packages\pymysql\connections.py", line 358, in __init__
    self.connect()
  File "C:\Users\ashukla\.virtualenvs\Tours_and_Travel-ejH2dMQI\Lib\site-packages\pymysql\connections.py", line 711, in connect
    raise exc
pymysql.err.OperationalError: (2003, "Can't connect to MySQL server on '127.0.0.1' ([WinError 10061] No connection could be made because the target machine actively refused it)")

The above exception was the direct cause of the following exception:

Traceback (most recent call last):
  File "c:\Users\ashukla\OneDrive - WatchGuard Technologies Inc\Desktop\Minor project\Tours and Travel\src\utils\initialize_app.py", line 43, in create_tables
    with DatabaseConnection() as connection:
         ^^^^^^^^^^^^^^^^^^^^
  File "c:\Users\ashukla\OneDrive - WatchGuard Technologies Inc\Desktop\Minor project\Tours and Travel\src\database\context_manager.py", line 22, in __init__
    self.setup_connection()
  File "c:\Users\ashukla\OneDrive - WatchGuard Technologies Inc\Desktop\Minor project\Tours and Travel\src\database\context_manager.py", line 48, in setup_connection
    raise pymysql.Error from e
pymysql.err.Error
19-02-2024 11:55:34 - 
Traceback (most recent call last):
  File "C:\Users\ashukla\.virtualenvs\Tours_and_Travel-ejH2dMQI\Lib\site-packages\pymysql\connections.py", line 644, in connect
    sock = socket.create_connection(
           ^^^^^^^^^^^^^^^^^^^^^^^^^
  File "C:\Program Files\Python311\Lib\socket.py", line 851, in create_connection
    raise exceptions[0]
  File "C:\Program Files\Python311\Lib\socket.py", line 836, in create_connection
    sock.connect(sa)
ConnectionRefusedError: [WinError 10061] No connection could be made because the target machine actively refused it

During handling of the above exception, another exception occurred:

Traceback (most recent call last):
  File "c:\Users\ashukla\OneDrive - WatchGuard Technologies Inc\Desktop\Minor project\Tours and Travel\src\database\context_manager.py", line 28, in setup_connection
    self.connection = pymysql.connect(
                      ^^^^^^^^^^^^^^^^
  File "C:\Users\ashukla\.virtualenvs\Tours_and_Travel-ejH2dMQI\Lib\site-packages\pymysql\connections.py", line 358, in __init__
    self.connect()
  File "C:\Users\ashukla\.virtualenvs\Tours_and_Travel-ejH2dMQI\Lib\site-packages\pymysql\connections.py", line 711, in connect
    raise exc
pymysql.err.OperationalError: (2003, "Can't connect to MySQL server on '127.0.0.1' ([WinError 10061] No connection could be made because the target machine actively refused it)")

The above exception was the direct cause of the following exception:

Traceback (most recent call last):
  File "c:\Users\ashukla\OneDrive - WatchGuard Technologies Inc\Desktop\Minor project\Tours and Travel\src\utils\initialize_app.py", line 43, in create_tables
    with DatabaseConnection() as connection:
         ^^^^^^^^^^^^^^^^^^^^
  File "c:\Users\ashukla\OneDrive - WatchGuard Technologies Inc\Desktop\Minor project\Tours and Travel\src\database\context_manager.py", line 22, in __init__
    self.setup_connection()
  File "c:\Users\ashukla\OneDrive - WatchGuard Technologies Inc\Desktop\Minor project\Tours and Travel\src\database\context_manager.py", line 48, in setup_connection
    raise pymysql.Error from e
pymysql.err.Error
19-02-2024 11:56:02 - 
Traceback (most recent call last):
  File "C:\Users\ashukla\.virtualenvs\Tours_and_Travel-ejH2dMQI\Lib\site-packages\pymysql\connections.py", line 644, in connect
    sock = socket.create_connection(
           ^^^^^^^^^^^^^^^^^^^^^^^^^
  File "C:\Program Files\Python311\Lib\socket.py", line 851, in create_connection
    raise exceptions[0]
  File "C:\Program Files\Python311\Lib\socket.py", line 836, in create_connection
    sock.connect(sa)
ConnectionRefusedError: [WinError 10061] No connection could be made because the target machine actively refused it

During handling of the above exception, another exception occurred:

Traceback (most recent call last):
  File "c:\Users\ashukla\OneDrive - WatchGuard Technologies Inc\Desktop\Minor project\Tours and Travel\src\database\context_manager.py", line 28, in setup_connection
    self.connection = pymysql.connect(
                      ^^^^^^^^^^^^^^^^
  File "C:\Users\ashukla\.virtualenvs\Tours_and_Travel-ejH2dMQI\Lib\site-packages\pymysql\connections.py", line 358, in __init__
    self.connect()
  File "C:\Users\ashukla\.virtualenvs\Tours_and_Travel-ejH2dMQI\Lib\site-packages\pymysql\connections.py", line 711, in connect
    raise exc
pymysql.err.OperationalError: (2003, "Can't connect to MySQL server on '127.0.0.1' ([WinError 10061] No connection could be made because the target machine actively refused it)")

The above exception was the direct cause of the following exception:

Traceback (most recent call last):
  File "c:\Users\ashukla\OneDrive - WatchGuard Technologies Inc\Desktop\Minor project\Tours and Travel\src\utils\initialize_app.py", line 43, in create_tables
    with DatabaseConnection() as connection:
         ^^^^^^^^^^^^^^^^^^^^
  File "c:\Users\ashukla\OneDrive - WatchGuard Technologies Inc\Desktop\Minor project\Tours and Travel\src\database\context_manager.py", line 22, in __init__
    self.setup_connection()
  File "c:\Users\ashukla\OneDrive - WatchGuard Technologies Inc\Desktop\Minor project\Tours and Travel\src\database\context_manager.py", line 48, in setup_connection
    raise pymysql.Error from e
pymysql.err.Error
19-02-2024 11:58:51 - 
Traceback (most recent call last):
  File "C:\Users\ashukla\.virtualenvs\Tours_and_Travel-ejH2dMQI\Lib\site-packages\pymysql\connections.py", line 644, in connect
    sock = socket.create_connection(
           ^^^^^^^^^^^^^^^^^^^^^^^^^
  File "C:\Program Files\Python311\Lib\socket.py", line 851, in create_connection
    raise exceptions[0]
  File "C:\Program Files\Python311\Lib\socket.py", line 836, in create_connection
    sock.connect(sa)
ConnectionRefusedError: [WinError 10061] No connection could be made because the target machine actively refused it

During handling of the above exception, another exception occurred:

Traceback (most recent call last):
  File "c:\Users\ashukla\OneDrive - WatchGuard Technologies Inc\Desktop\Minor project\Tours and Travel\src\database\context_manager.py", line 28, in setup_connection
    self.connection = pymysql.connect(
                      ^^^^^^^^^^^^^^^^
  File "C:\Users\ashukla\.virtualenvs\Tours_and_Travel-ejH2dMQI\Lib\site-packages\pymysql\connections.py", line 358, in __init__
    self.connect()
  File "C:\Users\ashukla\.virtualenvs\Tours_and_Travel-ejH2dMQI\Lib\site-packages\pymysql\connections.py", line 711, in connect
    raise exc
pymysql.err.OperationalError: (2003, "Can't connect to MySQL server on '127.0.0.1' ([WinError 10061] No connection could be made because the target machine actively refused it)")

The above exception was the direct cause of the following exception:

Traceback (most recent call last):
  File "c:\Users\ashukla\OneDrive - WatchGuard Technologies Inc\Desktop\Minor project\Tours and Travel\src\utils\initialize_app.py", line 43, in create_tables
    with DatabaseConnection() as connection:
         ^^^^^^^^^^^^^^^^^^^^
  File "c:\Users\ashukla\OneDrive - WatchGuard Technologies Inc\Desktop\Minor project\Tours and Travel\src\database\context_manager.py", line 22, in __init__
    self.setup_connection()
  File "c:\Users\ashukla\OneDrive - WatchGuard Technologies Inc\Desktop\Minor project\Tours and Travel\src\database\context_manager.py", line 48, in setup_connection
    raise pymysql.Error from e
pymysql.err.Error
